[2023-11-17 11:19:16,413: INFO: main: Welcome to our custom logger method]
[2023-11-17 11:21:33,896: INFO: main: Welcome to our custom logger method]
[2023-11-26 19:37:50,194: INFO: common: yaml file: config/config.yaml loaded successfully]
[2023-11-26 19:40:16,444: INFO: common: yaml file: config/config.yaml loaded successfully]
[2023-11-26 19:41:34,160: INFO: common: yaml file: config/config.yaml loaded successfully]
[2023-11-26 19:45:50,671: INFO: common: yaml file: config/config.yaml loaded successfully]
[2023-11-26 19:45:50,683: INFO: common: yaml file: params.yaml loaded successfully]
[2023-11-26 19:45:50,688: INFO: common: created directory at :artifacts]
[2023-11-26 19:46:52,519: INFO: common: yaml file: config/config.yaml loaded successfully]
[2023-11-26 19:46:52,524: INFO: common: yaml file: params.yaml loaded successfully]
[2023-11-26 19:46:52,543: INFO: common: created directory at :artifacts]
[2023-11-26 19:46:52,556: INFO: common: created directory at :artifacts/data_ingestion]
[2023-11-26 19:47:27,488: INFO: 2662514189: artifacts/data_ingestion/data.zip download! with following info: 
Connection: close
Content-Length: 24441500
Cache-Control: max-age=300
Content-Security-Policy: default-src 'none'; style-src 'unsafe-inline'; sandbox
Content-Type: application/zip
ETag: "165933e50795792296f76b85aaf91d3eb23e87d0eae076c6e4098708d6f973f4"
Strict-Transport-Security: max-age=31536000
X-Content-Type-Options: nosniff
X-Frame-Options: deny
X-XSS-Protection: 1; mode=block
X-GitHub-Request-Id: 73B0:B8CFB:2186FB:3B75AD:65635355
Accept-Ranges: bytes
Date: Sun, 26 Nov 2023 14:16:55 GMT
Via: 1.1 varnish
X-Served-By: cache-hyd1100035-HYD
X-Cache: MISS
X-Cache-Hits: 0
X-Timer: S1701008214.771950,VS0,VE1542
Vary: Authorization,Accept-Encoding,Origin
Access-Control-Allow-Origin: *
Cross-Origin-Resource-Policy: cross-origin
X-Fastly-Request-ID: e9fbf1b060a4477549bd7c3b34c5493e97cf861b
Expires: Sun, 26 Nov 2023 14:21:55 GMT
Source-Age: 1

]
[2023-11-26 20:12:15,931: INFO: main: >>>>>>>>>> stage Data Ingestion stage started <<<<<<<<<<]
[2023-11-26 20:12:15,934: INFO: common: yaml file: config/config.yaml loaded successfully]
[2023-11-26 20:12:15,935: INFO: common: yaml file: params.yaml loaded successfully]
[2023-11-26 20:12:15,936: INFO: common: created directory at :artifacts]
[2023-11-26 20:12:15,936: INFO: common: created directory at :artifacts/data_ingestion]
[2023-11-26 20:12:24,447: INFO: data_ingestion: artifacts/data_ingestion/data.zip download! with following info: 
Connection: close
Content-Length: 24441500
Cache-Control: max-age=300
Content-Security-Policy: default-src 'none'; style-src 'unsafe-inline'; sandbox
Content-Type: application/zip
ETag: "165933e50795792296f76b85aaf91d3eb23e87d0eae076c6e4098708d6f973f4"
Strict-Transport-Security: max-age=31536000
X-Content-Type-Options: nosniff
X-Frame-Options: deny
X-XSS-Protection: 1; mode=block
X-GitHub-Request-Id: 73B0:B8CFB:2186FB:3B75AD:65635355
Accept-Ranges: bytes
Date: Sun, 26 Nov 2023 14:42:17 GMT
Via: 1.1 varnish
X-Served-By: cache-hyd1100030-HYD
X-Cache: HIT
X-Cache-Hits: 0
X-Timer: S1701009737.772390,VS0,VE355
Vary: Authorization,Accept-Encoding,Origin
Access-Control-Allow-Origin: *
Cross-Origin-Resource-Policy: cross-origin
X-Fastly-Request-ID: c3bd6cfed92c8d31f3d214b9046df3467b3ebd8c
Expires: Sun, 26 Nov 2023 14:47:17 GMT
Source-Age: 0

]
[2023-11-26 20:12:25,233: INFO: main: >>>>>>>>>> stage Data Ingestion stage completed started <<<<

x============x<<<<<<]
[2023-11-27 16:15:27,404: INFO: common: yaml file: config/config.yaml loaded successfully]
[2023-11-27 16:15:27,426: INFO: common: yaml file: params.yaml loaded successfully]
[2023-11-27 16:15:27,435: INFO: common: created directory at :artifacts]
[2023-11-27 16:16:53,078: INFO: common: yaml file: config/config.yaml loaded successfully]
[2023-11-27 16:16:53,081: INFO: common: yaml file: params.yaml loaded successfully]
[2023-11-27 16:16:53,085: INFO: common: created directory at :artifacts]
[2023-11-27 16:16:55,293: INFO: common: yaml file: config/config.yaml loaded successfully]
[2023-11-27 16:16:55,302: INFO: common: yaml file: params.yaml loaded successfully]
[2023-11-27 16:16:55,314: INFO: common: created directory at :artifacts]
[2023-11-27 16:17:54,105: INFO: common: yaml file: config/config.yaml loaded successfully]
[2023-11-27 16:17:54,109: INFO: common: yaml file: params.yaml loaded successfully]
[2023-11-27 16:17:54,111: INFO: common: created directory at :artifacts]
[2023-11-27 16:17:56,651: INFO: common: yaml file: config/config.yaml loaded successfully]
[2023-11-27 16:17:56,663: INFO: common: yaml file: params.yaml loaded successfully]
[2023-11-27 16:17:56,670: INFO: common: created directory at :artifacts]
[2023-11-27 16:17:57,374: INFO: common: yaml file: config/config.yaml loaded successfully]
[2023-11-27 16:17:57,379: INFO: common: yaml file: params.yaml loaded successfully]
[2023-11-27 16:17:57,388: INFO: common: created directory at :artifacts]
[2023-11-27 16:17:57,957: INFO: common: yaml file: config/config.yaml loaded successfully]
[2023-11-27 16:17:57,962: INFO: common: yaml file: params.yaml loaded successfully]
[2023-11-27 16:17:57,971: INFO: common: created directory at :artifacts]
[2023-11-27 16:24:21,318: INFO: common: yaml file: config/config.yaml loaded successfully]
[2023-11-27 16:24:21,344: INFO: common: yaml file: params.yaml loaded successfully]
[2023-11-27 16:24:21,349: INFO: common: created directory at :artifacts]
[2023-11-27 16:25:33,583: INFO: common: yaml file: config/config.yaml loaded successfully]
[2023-11-27 16:25:33,623: INFO: common: yaml file: params.yaml loaded successfully]
[2023-11-27 16:25:33,636: INFO: common: created directory at :artifacts]
[2023-11-27 16:28:09,186: INFO: common: yaml file: config/config.yaml loaded successfully]
[2023-11-27 16:28:09,224: INFO: common: yaml file: params.yaml loaded successfully]
[2023-11-27 16:28:09,232: INFO: common: created directory at :artifacts]
[2023-11-27 16:28:09,237: INFO: common: created directory at :artifacts/data_validation]
[2023-11-27 16:28:23,100: INFO: common: yaml file: config/config.yaml loaded successfully]
[2023-11-27 16:28:23,112: INFO: common: yaml file: params.yaml loaded successfully]
[2023-11-27 16:28:23,145: INFO: common: created directory at :artifacts]
[2023-11-27 16:28:23,162: INFO: common: created directory at :artifacts/data_validation]
[2023-11-27 16:30:10,855: INFO: common: yaml file: config/config.yaml loaded successfully]
[2023-11-27 16:30:10,859: INFO: common: yaml file: params.yaml loaded successfully]
[2023-11-27 16:30:10,862: INFO: common: created directory at :artifacts]
[2023-11-27 16:30:10,864: INFO: common: created directory at :artifacts/data_validation]
[2023-11-27 16:41:34,400: INFO: main: >>>>>>>>>> stage Data Ingestion stage started <<<<<<<<<<]
[2023-11-27 16:41:34,402: INFO: common: yaml file: config/config.yaml loaded successfully]
[2023-11-27 16:41:34,403: INFO: common: yaml file: params.yaml loaded successfully]
[2023-11-27 16:41:34,404: INFO: common: created directory at :artifacts]
[2023-11-27 16:41:34,404: INFO: common: created directory at :artifacts/data_ingestion]
[2023-11-27 16:41:58,649: INFO: data_ingestion: artifacts/data_ingestion/data.zip download! with following info: 
Connection: close
Content-Length: 24441500
Cache-Control: max-age=300
Content-Security-Policy: default-src 'none'; style-src 'unsafe-inline'; sandbox
Content-Type: application/zip
ETag: "165933e50795792296f76b85aaf91d3eb23e87d0eae076c6e4098708d6f973f4"
Strict-Transport-Security: max-age=31536000
X-Content-Type-Options: nosniff
X-Frame-Options: deny
X-XSS-Protection: 1; mode=block
X-GitHub-Request-Id: 17A0:191F3:6376:900E:65647967
Accept-Ranges: bytes
Date: Mon, 27 Nov 2023 11:11:37 GMT
Via: 1.1 varnish
X-Served-By: cache-hyd1100028-HYD
X-Cache: MISS
X-Cache-Hits: 0
X-Timer: S1701083496.684119,VS0,VE1606
Vary: Authorization,Accept-Encoding,Origin
Access-Control-Allow-Origin: *
Cross-Origin-Resource-Policy: cross-origin
X-Fastly-Request-ID: 490284cde529c2c899947e7b173cece47d1b4cc6
Expires: Mon, 27 Nov 2023 11:16:37 GMT
Source-Age: 1

]
[2023-11-27 16:41:59,153: INFO: main: >>>>>>>>>> stage Data Ingestion stage completed started <<<<

x============x<<<<<<]
[2023-11-27 16:41:59,153: INFO: main: >>>>>>>>>> stage Data Validation stage started <<<<<<<<<<]
[2023-11-27 16:41:59,159: INFO: common: yaml file: config/config.yaml loaded successfully]
[2023-11-27 16:41:59,161: INFO: common: yaml file: params.yaml loaded successfully]
[2023-11-27 16:41:59,161: INFO: common: created directory at :artifacts]
[2023-11-27 16:41:59,162: INFO: common: created directory at :artifacts/data_validation]
[2023-11-27 16:41:59,163: INFO: main: >>>>>>>>>> stage Data Validation stage completed started <<<<

x============x<<<<<<]
[2023-11-27 17:59:27,023: INFO: common: yaml file: config/config.yaml loaded successfully]
[2023-11-27 17:59:27,035: INFO: common: yaml file: params.yaml loaded successfully]
[2023-11-27 17:59:27,038: INFO: common: created directory at :artifacts]
[2023-11-27 17:59:27,041: INFO: common: created directory at :artifacts/data_transformation]
[2023-11-27 17:59:43,973: INFO: common: yaml file: config/config.yaml loaded successfully]
[2023-11-27 17:59:43,984: INFO: common: yaml file: params.yaml loaded successfully]
[2023-11-27 17:59:43,985: INFO: common: created directory at :artifacts]
[2023-11-27 17:59:43,987: INFO: common: created directory at :artifacts/data_transformation]
[2023-11-27 18:03:12,648: INFO: common: yaml file: config/config.yaml loaded successfully]
[2023-11-27 18:03:12,651: INFO: common: yaml file: params.yaml loaded successfully]
[2023-11-27 18:03:12,652: INFO: common: created directory at :artifacts]
[2023-11-27 18:03:12,654: INFO: common: created directory at :artifacts/data_transformation]
[2023-11-27 18:03:58,652: INFO: common: yaml file: config/config.yaml loaded successfully]
[2023-11-27 18:03:58,659: INFO: common: yaml file: params.yaml loaded successfully]
[2023-11-27 18:03:58,661: INFO: common: created directory at :artifacts]
[2023-11-27 18:03:58,663: INFO: common: created directory at :artifacts/data_transformation]
[2023-11-27 18:21:38,188: INFO: main: >>>>>>>>>> stage Data Ingestion stage started <<<<<<<<<<]
[2023-11-27 18:21:38,192: INFO: common: yaml file: config/config.yaml loaded successfully]
[2023-11-27 18:21:38,196: INFO: common: yaml file: params.yaml loaded successfully]
[2023-11-27 18:21:38,197: INFO: common: created directory at :artifacts]
[2023-11-27 18:21:38,197: INFO: common: created directory at :artifacts/data_ingestion]
[2023-11-27 18:22:06,733: INFO: data_ingestion: artifacts/data_ingestion/data.zip download! with following info: 
Connection: close
Content-Length: 24441500
Cache-Control: max-age=300
Content-Security-Policy: default-src 'none'; style-src 'unsafe-inline'; sandbox
Content-Type: application/zip
ETag: "165933e50795792296f76b85aaf91d3eb23e87d0eae076c6e4098708d6f973f4"
Strict-Transport-Security: max-age=31536000
X-Content-Type-Options: nosniff
X-Frame-Options: deny
X-XSS-Protection: 1; mode=block
X-GitHub-Request-Id: D30E:29BF6A:10B2CB:1E93CF:656490D8
Accept-Ranges: bytes
Date: Mon, 27 Nov 2023 12:51:40 GMT
Via: 1.1 varnish
X-Served-By: cache-hyd1100025-HYD
X-Cache: MISS
X-Cache-Hits: 0
X-Timer: S1701089499.912356,VS0,VE1547
Vary: Authorization,Accept-Encoding,Origin
Access-Control-Allow-Origin: *
Cross-Origin-Resource-Policy: cross-origin
X-Fastly-Request-ID: e38ab7307d0a2013548375127fd9033c29ad335d
Expires: Mon, 27 Nov 2023 12:56:40 GMT
Source-Age: 1

]
[2023-11-27 18:22:07,186: INFO: main: >>>>>>>>>> stage Data Ingestion stage completed started <<<<

x============x<<<<<<]
[2023-11-27 18:22:07,186: INFO: main: >>>>>>>>>> stage Data Validation stage started <<<<<<<<<<]
[2023-11-27 18:22:07,190: INFO: common: yaml file: config/config.yaml loaded successfully]
[2023-11-27 18:22:07,191: INFO: common: yaml file: params.yaml loaded successfully]
[2023-11-27 18:22:07,191: INFO: common: created directory at :artifacts]
[2023-11-27 18:22:07,192: INFO: common: created directory at :artifacts/data_validation]
[2023-11-27 18:22:07,194: INFO: main: >>>>>>>>>> stage Data Validation stage completed started <<<<

x============x<<<<<<]
[2023-11-27 18:22:07,194: INFO: main: >>>>>>>>>> stage Data Transformation stage started <<<<<<<<<<]
[2023-11-27 18:22:07,198: INFO: common: yaml file: config/config.yaml loaded successfully]
[2023-11-27 18:22:07,199: INFO: common: yaml file: params.yaml loaded successfully]
[2023-11-27 18:22:07,199: INFO: common: created directory at :artifacts]
[2023-11-27 18:22:07,200: INFO: common: created directory at :artifacts/data_transformation]
[2023-11-27 18:22:22,109: INFO: main: >>>>>>>>>> stage Data Transformation stage completed started <<<<

x============x<<<<<<]
[2023-11-27 23:17:06,135: INFO: common: yaml file: config/config.yaml loaded successfully]
[2023-11-27 23:17:06,198: INFO: common: yaml file: params.yaml loaded successfully]
[2023-11-27 23:17:06,201: INFO: common: created directory at :artifacts]
[2023-11-27 23:17:06,205: INFO: common: created directory at :artifacts/model_trainer]
[2023-11-27 23:21:30,567: INFO: common: yaml file: config/config.yaml loaded successfully]
[2023-11-27 23:21:30,574: INFO: common: yaml file: params.yaml loaded successfully]
[2023-11-27 23:21:30,578: INFO: common: created directory at :artifacts]
[2023-11-27 23:21:30,583: INFO: common: created directory at :artifacts/model_trainer]
[2023-11-27 23:21:37,298: INFO: common: yaml file: config/config.yaml loaded successfully]
[2023-11-27 23:21:37,306: INFO: common: yaml file: params.yaml loaded successfully]
[2023-11-27 23:21:37,310: INFO: common: created directory at :artifacts]
[2023-11-27 23:21:37,313: INFO: common: created directory at :artifacts/model_trainer]
[2023-11-27 23:23:03,935: INFO: common: yaml file: config/config.yaml loaded successfully]
[2023-11-27 23:23:03,943: INFO: common: yaml file: params.yaml loaded successfully]
[2023-11-27 23:23:03,947: INFO: common: created directory at :artifacts]
[2023-11-27 23:23:03,951: INFO: common: created directory at :artifacts/model_trainer]
[2023-11-27 23:23:14,049: INFO: common: yaml file: config/config.yaml loaded successfully]
[2023-11-27 23:23:14,067: INFO: common: yaml file: params.yaml loaded successfully]
[2023-11-27 23:23:14,079: INFO: common: created directory at :artifacts]
[2023-11-27 23:23:14,105: INFO: common: created directory at :artifacts/model_trainer]
[2023-11-27 23:49:32,795: INFO: main: >>>>>>>>>> stage Data Ingestion stage started <<<<<<<<<<]
[2023-11-27 23:49:32,799: INFO: common: yaml file: config/config.yaml loaded successfully]
[2023-11-27 23:49:32,802: INFO: common: yaml file: params.yaml loaded successfully]
[2023-11-27 23:49:32,802: INFO: common: created directory at :artifacts]
[2023-11-27 23:49:32,802: INFO: common: created directory at :artifacts/data_ingestion]
[2023-11-27 23:49:40,913: INFO: data_ingestion: artifacts/data_ingestion/data.zip download! with following info: 
Connection: close
Content-Length: 24441500
Cache-Control: max-age=300
Content-Security-Policy: default-src 'none'; style-src 'unsafe-inline'; sandbox
Content-Type: application/zip
ETag: "165933e50795792296f76b85aaf91d3eb23e87d0eae076c6e4098708d6f973f4"
Strict-Transport-Security: max-age=31536000
X-Content-Type-Options: nosniff
X-Frame-Options: deny
X-XSS-Protection: 1; mode=block
X-GitHub-Request-Id: 8442:2EE0A3:DFCDE:196DC9:6564DDB3
Accept-Ranges: bytes
Date: Mon, 27 Nov 2023 18:19:34 GMT
Via: 1.1 varnish
X-Served-By: cache-hyd1100028-HYD
X-Cache: MISS
X-Cache-Hits: 0
X-Timer: S1701109174.670881,VS0,VE1321
Vary: Authorization,Accept-Encoding,Origin
Access-Control-Allow-Origin: *
Cross-Origin-Resource-Policy: cross-origin
X-Fastly-Request-ID: c77e0c5a6a362c5690355cdd623b1d6e7729d38c
Expires: Mon, 27 Nov 2023 18:24:34 GMT
Source-Age: 1

]
[2023-11-27 23:49:41,276: INFO: main: >>>>>>>>>> stage Data Ingestion stage completed started <<<<

x============x<<<<<<]
[2023-11-27 23:49:41,277: INFO: main: >>>>>>>>>> stage Data Validation stage started <<<<<<<<<<]
[2023-11-27 23:49:41,279: INFO: common: yaml file: config/config.yaml loaded successfully]
[2023-11-27 23:49:41,281: INFO: common: yaml file: params.yaml loaded successfully]
[2023-11-27 23:49:41,281: INFO: common: created directory at :artifacts]
[2023-11-27 23:49:41,281: INFO: common: created directory at :artifacts/data_validation]
[2023-11-27 23:49:41,283: INFO: main: >>>>>>>>>> stage Data Validation stage completed started <<<<

x============x<<<<<<]
[2023-11-27 23:49:41,283: INFO: main: >>>>>>>>>> stage Data Transformation stage started <<<<<<<<<<]
[2023-11-27 23:49:41,286: INFO: common: yaml file: config/config.yaml loaded successfully]
[2023-11-27 23:49:41,287: INFO: common: yaml file: params.yaml loaded successfully]
[2023-11-27 23:49:41,288: INFO: common: created directory at :artifacts]
[2023-11-27 23:49:41,288: INFO: common: created directory at :artifacts/data_transformation]
[2023-11-27 23:49:53,558: INFO: main: >>>>>>>>>> stage Data Transformation stage completed started <<<<

x============x<<<<<<]
[2023-11-27 23:49:53,558: INFO: main: >>>>>>>>>> stage Model Training stage started <<<<<<<<<<]
[2023-11-27 23:49:53,561: INFO: common: yaml file: config/config.yaml loaded successfully]
[2023-11-27 23:49:53,562: INFO: common: yaml file: params.yaml loaded successfully]
[2023-11-27 23:49:53,562: INFO: common: created directory at :artifacts]
[2023-11-27 23:49:53,563: INFO: common: created directory at :artifacts/model_trainer]
[2023-11-28 01:51:34,344: WARNING: file_download: Error while downloading from https://cdn-lfs.huggingface.co/google/pegasus-cnn_dailymail/cf34e28157605d3ced3bd184820ea2a9d9a30b69f4bb1df4aaa4145d0850290e?response-content-disposition=attachment%3B+filename*%3DUTF-8%27%27pytorch_model.bin%3B+filename%3D%22pytorch_model.bin%22%3B&response-content-type=application%2Foctet-stream&Expires=1701364193&Policy=eyJTdGF0ZW1lbnQiOlt7IkNvbmRpdGlvbiI6eyJEYXRlTGVzc1RoYW4iOnsiQVdTOkVwb2NoVGltZSI6MTcwMTM2NDE5M319LCJSZXNvdXJjZSI6Imh0dHBzOi8vY2RuLWxmcy5odWdnaW5nZmFjZS5jby9nb29nbGUvcGVnYXN1cy1jbm5fZGFpbHltYWlsL2NmMzRlMjgxNTc2MDVkM2NlZDNiZDE4NDgyMGVhMmE5ZDlhMzBiNjlmNGJiMWRmNGFhYTQxNDVkMDg1MDI5MGU%7EcmVzcG9uc2UtY29udGVudC1kaXNwb3NpdGlvbj0qJnJlc3BvbnNlLWNvbnRlbnQtdHlwZT0qIn1dfQ__&Signature=Zi1gai%7EjzGappSX6X6%7E1FsVA47q2sSKkxEp52CYRSecohaAjeVwly2N%7Em2AcwaCB3XTjxq2JtB%7EcZuwPSiEkBoBtQIwmwKWuMa5JU-qOGxqbzmPsd-ssWdo3GlpsHx13u8fJCSREZzyXxBLyLEohvswE4f2RDrbJFbfURDPTWq3Aru6EuZZHutFjxDfdzjNgHxi4erjWPMQwhWLnc0hsd-r5cB9kL8OQ87a-pd5BGTcwPrAhXkbKdJcnc758VOkIaQokVowbumL1MvUVwGDlZubVStzjlpmRaLcIZV40PV3Y5O0NbGoTitvhLoDPdRsiC26evbZF6TVUB%7EnOmqOGKA__&Key-Pair-Id=KVTP0A1DKRTAX: HTTPSConnectionPool(host='cdn-lfs.huggingface.co', port=443): Read timed out.
Trying to resume download...]
[2023-11-28 05:52:10,209: WARNING: file_download: Error while downloading from https://cdn-lfs.huggingface.co/google/pegasus-cnn_dailymail/cf34e28157605d3ced3bd184820ea2a9d9a30b69f4bb1df4aaa4145d0850290e?response-content-disposition=attachment%3B+filename*%3DUTF-8%27%27pytorch_model.bin%3B+filename%3D%22pytorch_model.bin%22%3B&response-content-type=application%2Foctet-stream&Expires=1701364193&Policy=eyJTdGF0ZW1lbnQiOlt7IkNvbmRpdGlvbiI6eyJEYXRlTGVzc1RoYW4iOnsiQVdTOkVwb2NoVGltZSI6MTcwMTM2NDE5M319LCJSZXNvdXJjZSI6Imh0dHBzOi8vY2RuLWxmcy5odWdnaW5nZmFjZS5jby9nb29nbGUvcGVnYXN1cy1jbm5fZGFpbHltYWlsL2NmMzRlMjgxNTc2MDVkM2NlZDNiZDE4NDgyMGVhMmE5ZDlhMzBiNjlmNGJiMWRmNGFhYTQxNDVkMDg1MDI5MGU%7EcmVzcG9uc2UtY29udGVudC1kaXNwb3NpdGlvbj0qJnJlc3BvbnNlLWNvbnRlbnQtdHlwZT0qIn1dfQ__&Signature=Zi1gai%7EjzGappSX6X6%7E1FsVA47q2sSKkxEp52CYRSecohaAjeVwly2N%7Em2AcwaCB3XTjxq2JtB%7EcZuwPSiEkBoBtQIwmwKWuMa5JU-qOGxqbzmPsd-ssWdo3GlpsHx13u8fJCSREZzyXxBLyLEohvswE4f2RDrbJFbfURDPTWq3Aru6EuZZHutFjxDfdzjNgHxi4erjWPMQwhWLnc0hsd-r5cB9kL8OQ87a-pd5BGTcwPrAhXkbKdJcnc758VOkIaQokVowbumL1MvUVwGDlZubVStzjlpmRaLcIZV40PV3Y5O0NbGoTitvhLoDPdRsiC26evbZF6TVUB%7EnOmqOGKA__&Key-Pair-Id=KVTP0A1DKRTAX: HTTPSConnectionPool(host='cdn-lfs.huggingface.co', port=443): Read timed out.
Trying to resume download...]
[2023-11-28 07:52:27,963: WARNING: file_download: Error while downloading from https://cdn-lfs.huggingface.co/google/pegasus-cnn_dailymail/cf34e28157605d3ced3bd184820ea2a9d9a30b69f4bb1df4aaa4145d0850290e?response-content-disposition=attachment%3B+filename*%3DUTF-8%27%27pytorch_model.bin%3B+filename%3D%22pytorch_model.bin%22%3B&response-content-type=application%2Foctet-stream&Expires=1701364193&Policy=eyJTdGF0ZW1lbnQiOlt7IkNvbmRpdGlvbiI6eyJEYXRlTGVzc1RoYW4iOnsiQVdTOkVwb2NoVGltZSI6MTcwMTM2NDE5M319LCJSZXNvdXJjZSI6Imh0dHBzOi8vY2RuLWxmcy5odWdnaW5nZmFjZS5jby9nb29nbGUvcGVnYXN1cy1jbm5fZGFpbHltYWlsL2NmMzRlMjgxNTc2MDVkM2NlZDNiZDE4NDgyMGVhMmE5ZDlhMzBiNjlmNGJiMWRmNGFhYTQxNDVkMDg1MDI5MGU%7EcmVzcG9uc2UtY29udGVudC1kaXNwb3NpdGlvbj0qJnJlc3BvbnNlLWNvbnRlbnQtdHlwZT0qIn1dfQ__&Signature=Zi1gai%7EjzGappSX6X6%7E1FsVA47q2sSKkxEp52CYRSecohaAjeVwly2N%7Em2AcwaCB3XTjxq2JtB%7EcZuwPSiEkBoBtQIwmwKWuMa5JU-qOGxqbzmPsd-ssWdo3GlpsHx13u8fJCSREZzyXxBLyLEohvswE4f2RDrbJFbfURDPTWq3Aru6EuZZHutFjxDfdzjNgHxi4erjWPMQwhWLnc0hsd-r5cB9kL8OQ87a-pd5BGTcwPrAhXkbKdJcnc758VOkIaQokVowbumL1MvUVwGDlZubVStzjlpmRaLcIZV40PV3Y5O0NbGoTitvhLoDPdRsiC26evbZF6TVUB%7EnOmqOGKA__&Key-Pair-Id=KVTP0A1DKRTAX: HTTPSConnectionPool(host='cdn-lfs.huggingface.co', port=443): Read timed out.
Trying to resume download...]
[2023-11-28 10:57:38,469: WARNING: file_download: Error while downloading from https://cdn-lfs.huggingface.co/google/pegasus-cnn_dailymail/cf34e28157605d3ced3bd184820ea2a9d9a30b69f4bb1df4aaa4145d0850290e?response-content-disposition=attachment%3B+filename*%3DUTF-8%27%27pytorch_model.bin%3B+filename%3D%22pytorch_model.bin%22%3B&response-content-type=application%2Foctet-stream&Expires=1701364193&Policy=eyJTdGF0ZW1lbnQiOlt7IkNvbmRpdGlvbiI6eyJEYXRlTGVzc1RoYW4iOnsiQVdTOkVwb2NoVGltZSI6MTcwMTM2NDE5M319LCJSZXNvdXJjZSI6Imh0dHBzOi8vY2RuLWxmcy5odWdnaW5nZmFjZS5jby9nb29nbGUvcGVnYXN1cy1jbm5fZGFpbHltYWlsL2NmMzRlMjgxNTc2MDVkM2NlZDNiZDE4NDgyMGVhMmE5ZDlhMzBiNjlmNGJiMWRmNGFhYTQxNDVkMDg1MDI5MGU%7EcmVzcG9uc2UtY29udGVudC1kaXNwb3NpdGlvbj0qJnJlc3BvbnNlLWNvbnRlbnQtdHlwZT0qIn1dfQ__&Signature=Zi1gai%7EjzGappSX6X6%7E1FsVA47q2sSKkxEp52CYRSecohaAjeVwly2N%7Em2AcwaCB3XTjxq2JtB%7EcZuwPSiEkBoBtQIwmwKWuMa5JU-qOGxqbzmPsd-ssWdo3GlpsHx13u8fJCSREZzyXxBLyLEohvswE4f2RDrbJFbfURDPTWq3Aru6EuZZHutFjxDfdzjNgHxi4erjWPMQwhWLnc0hsd-r5cB9kL8OQ87a-pd5BGTcwPrAhXkbKdJcnc758VOkIaQokVowbumL1MvUVwGDlZubVStzjlpmRaLcIZV40PV3Y5O0NbGoTitvhLoDPdRsiC26evbZF6TVUB%7EnOmqOGKA__&Key-Pair-Id=KVTP0A1DKRTAX: HTTPSConnectionPool(host='cdn-lfs.huggingface.co', port=443): Read timed out.
Trying to resume download...]
[2023-11-28 10:57:39,579: ERROR: main: (MaxRetryError("HTTPSConnectionPool(host='cdn-lfs.huggingface.co', port=443): Max retries exceeded with url: /google/pegasus-cnn_dailymail/cf34e28157605d3ced3bd184820ea2a9d9a30b69f4bb1df4aaa4145d0850290e?response-content-disposition=attachment%3B+filename*%3DUTF-8%27%27pytorch_model.bin%3B+filename%3D%22pytorch_model.bin%22%3B&response-content-type=application%2Foctet-stream&Expires=1701364193&Policy=eyJTdGF0ZW1lbnQiOlt7IkNvbmRpdGlvbiI6eyJEYXRlTGVzc1RoYW4iOnsiQVdTOkVwb2NoVGltZSI6MTcwMTM2NDE5M319LCJSZXNvdXJjZSI6Imh0dHBzOi8vY2RuLWxmcy5odWdnaW5nZmFjZS5jby9nb29nbGUvcGVnYXN1cy1jbm5fZGFpbHltYWlsL2NmMzRlMjgxNTc2MDVkM2NlZDNiZDE4NDgyMGVhMmE5ZDlhMzBiNjlmNGJiMWRmNGFhYTQxNDVkMDg1MDI5MGU~cmVzcG9uc2UtY29udGVudC1kaXNwb3NpdGlvbj0qJnJlc3BvbnNlLWNvbnRlbnQtdHlwZT0qIn1dfQ__&Signature=Zi1gai~jzGappSX6X6~1FsVA47q2sSKkxEp52CYRSecohaAjeVwly2N~m2AcwaCB3XTjxq2JtB~cZuwPSiEkBoBtQIwmwKWuMa5JU-qOGxqbzmPsd-ssWdo3GlpsHx13u8fJCSREZzyXxBLyLEohvswE4f2RDrbJFbfURDPTWq3Aru6EuZZHutFjxDfdzjNgHxi4erjWPMQwhWLnc0hsd-r5cB9kL8OQ87a-pd5BGTcwPrAhXkbKdJcnc758VOkIaQokVowbumL1MvUVwGDlZubVStzjlpmRaLcIZV40PV3Y5O0NbGoTitvhLoDPdRsiC26evbZF6TVUB~nOmqOGKA__&Key-Pair-Id=KVTP0A1DKRTAX (Caused by NewConnectionError('<urllib3.connection.HTTPSConnection object at 0x7f7b27251820>: Failed to establish a new connection: [Errno 8] nodename nor servname provided, or not known'))"), '(Request ID: 92aaa4f5-4af8-4af0-bf96-07e3c9237be7)')]
Traceback (most recent call last):
  File "/Users/snehalmachan/opt/anaconda3/envs/textS/lib/python3.8/site-packages/urllib3/response.py", line 444, in _error_catcher
    yield
  File "/Users/snehalmachan/opt/anaconda3/envs/textS/lib/python3.8/site-packages/urllib3/response.py", line 567, in read
    data = self._fp_read(amt) if not fp_closed else b""
  File "/Users/snehalmachan/opt/anaconda3/envs/textS/lib/python3.8/site-packages/urllib3/response.py", line 533, in _fp_read
    return self._fp.read(amt) if amt is not None else self._fp.read()
  File "/Users/snehalmachan/opt/anaconda3/envs/textS/lib/python3.8/http/client.py", line 459, in read
    n = self.readinto(b)
  File "/Users/snehalmachan/opt/anaconda3/envs/textS/lib/python3.8/http/client.py", line 503, in readinto
    n = self.fp.readinto(b)
  File "/Users/snehalmachan/opt/anaconda3/envs/textS/lib/python3.8/socket.py", line 669, in readinto
    return self._sock.recv_into(b)
  File "/Users/snehalmachan/opt/anaconda3/envs/textS/lib/python3.8/ssl.py", line 1274, in recv_into
    return self.read(nbytes, buffer)
  File "/Users/snehalmachan/opt/anaconda3/envs/textS/lib/python3.8/ssl.py", line 1132, in read
    return self._sslobj.read(len, buffer)
socket.timeout: The read operation timed out

During handling of the above exception, another exception occurred:

Traceback (most recent call last):
  File "/Users/snehalmachan/opt/anaconda3/envs/textS/lib/python3.8/site-packages/requests/models.py", line 816, in generate
    yield from self.raw.stream(chunk_size, decode_content=True)
  File "/Users/snehalmachan/opt/anaconda3/envs/textS/lib/python3.8/site-packages/urllib3/response.py", line 628, in stream
    data = self.read(amt=amt, decode_content=decode_content)
  File "/Users/snehalmachan/opt/anaconda3/envs/textS/lib/python3.8/site-packages/urllib3/response.py", line 593, in read
    raise IncompleteRead(self._fp_bytes_read, self.length_remaining)
  File "/Users/snehalmachan/opt/anaconda3/envs/textS/lib/python3.8/contextlib.py", line 131, in __exit__
    self.gen.throw(type, value, traceback)
  File "/Users/snehalmachan/opt/anaconda3/envs/textS/lib/python3.8/site-packages/urllib3/response.py", line 449, in _error_catcher
    raise ReadTimeoutError(self._pool, None, "Read timed out.")
urllib3.exceptions.ReadTimeoutError: HTTPSConnectionPool(host='cdn-lfs.huggingface.co', port=443): Read timed out.

During handling of the above exception, another exception occurred:

Traceback (most recent call last):
  File "/Users/snehalmachan/opt/anaconda3/envs/textS/lib/python3.8/site-packages/huggingface_hub/file_download.py", line 541, in http_get
    for chunk in r.iter_content(chunk_size=DOWNLOAD_CHUNK_SIZE):
  File "/Users/snehalmachan/opt/anaconda3/envs/textS/lib/python3.8/site-packages/requests/models.py", line 822, in generate
    raise ConnectionError(e)
requests.exceptions.ConnectionError: HTTPSConnectionPool(host='cdn-lfs.huggingface.co', port=443): Read timed out.

During handling of the above exception, another exception occurred:

Traceback (most recent call last):
  File "/Users/snehalmachan/opt/anaconda3/envs/textS/lib/python3.8/site-packages/urllib3/response.py", line 444, in _error_catcher
    yield
  File "/Users/snehalmachan/opt/anaconda3/envs/textS/lib/python3.8/site-packages/urllib3/response.py", line 567, in read
    data = self._fp_read(amt) if not fp_closed else b""
  File "/Users/snehalmachan/opt/anaconda3/envs/textS/lib/python3.8/site-packages/urllib3/response.py", line 533, in _fp_read
    return self._fp.read(amt) if amt is not None else self._fp.read()
  File "/Users/snehalmachan/opt/anaconda3/envs/textS/lib/python3.8/http/client.py", line 459, in read
    n = self.readinto(b)
  File "/Users/snehalmachan/opt/anaconda3/envs/textS/lib/python3.8/http/client.py", line 503, in readinto
    n = self.fp.readinto(b)
  File "/Users/snehalmachan/opt/anaconda3/envs/textS/lib/python3.8/socket.py", line 669, in readinto
    return self._sock.recv_into(b)
  File "/Users/snehalmachan/opt/anaconda3/envs/textS/lib/python3.8/ssl.py", line 1274, in recv_into
    return self.read(nbytes, buffer)
  File "/Users/snehalmachan/opt/anaconda3/envs/textS/lib/python3.8/ssl.py", line 1132, in read
    return self._sslobj.read(len, buffer)
socket.timeout: The read operation timed out

During handling of the above exception, another exception occurred:

Traceback (most recent call last):
  File "/Users/snehalmachan/opt/anaconda3/envs/textS/lib/python3.8/site-packages/requests/models.py", line 816, in generate
    yield from self.raw.stream(chunk_size, decode_content=True)
  File "/Users/snehalmachan/opt/anaconda3/envs/textS/lib/python3.8/site-packages/urllib3/response.py", line 628, in stream
    data = self.read(amt=amt, decode_content=decode_content)
  File "/Users/snehalmachan/opt/anaconda3/envs/textS/lib/python3.8/site-packages/urllib3/response.py", line 593, in read
    raise IncompleteRead(self._fp_bytes_read, self.length_remaining)
  File "/Users/snehalmachan/opt/anaconda3/envs/textS/lib/python3.8/contextlib.py", line 131, in __exit__
    self.gen.throw(type, value, traceback)
  File "/Users/snehalmachan/opt/anaconda3/envs/textS/lib/python3.8/site-packages/urllib3/response.py", line 449, in _error_catcher
    raise ReadTimeoutError(self._pool, None, "Read timed out.")
urllib3.exceptions.ReadTimeoutError: HTTPSConnectionPool(host='cdn-lfs.huggingface.co', port=443): Read timed out.

During handling of the above exception, another exception occurred:

Traceback (most recent call last):
  File "/Users/snehalmachan/opt/anaconda3/envs/textS/lib/python3.8/site-packages/huggingface_hub/file_download.py", line 541, in http_get
    for chunk in r.iter_content(chunk_size=DOWNLOAD_CHUNK_SIZE):
  File "/Users/snehalmachan/opt/anaconda3/envs/textS/lib/python3.8/site-packages/requests/models.py", line 822, in generate
    raise ConnectionError(e)
requests.exceptions.ConnectionError: HTTPSConnectionPool(host='cdn-lfs.huggingface.co', port=443): Read timed out.

During handling of the above exception, another exception occurred:

Traceback (most recent call last):
  File "/Users/snehalmachan/opt/anaconda3/envs/textS/lib/python3.8/site-packages/urllib3/response.py", line 444, in _error_catcher
    yield
  File "/Users/snehalmachan/opt/anaconda3/envs/textS/lib/python3.8/site-packages/urllib3/response.py", line 567, in read
    data = self._fp_read(amt) if not fp_closed else b""
  File "/Users/snehalmachan/opt/anaconda3/envs/textS/lib/python3.8/site-packages/urllib3/response.py", line 533, in _fp_read
    return self._fp.read(amt) if amt is not None else self._fp.read()
  File "/Users/snehalmachan/opt/anaconda3/envs/textS/lib/python3.8/http/client.py", line 459, in read
    n = self.readinto(b)
  File "/Users/snehalmachan/opt/anaconda3/envs/textS/lib/python3.8/http/client.py", line 503, in readinto
    n = self.fp.readinto(b)
  File "/Users/snehalmachan/opt/anaconda3/envs/textS/lib/python3.8/socket.py", line 669, in readinto
    return self._sock.recv_into(b)
  File "/Users/snehalmachan/opt/anaconda3/envs/textS/lib/python3.8/ssl.py", line 1274, in recv_into
    return self.read(nbytes, buffer)
  File "/Users/snehalmachan/opt/anaconda3/envs/textS/lib/python3.8/ssl.py", line 1132, in read
    return self._sslobj.read(len, buffer)
socket.timeout: The read operation timed out

During handling of the above exception, another exception occurred:

Traceback (most recent call last):
  File "/Users/snehalmachan/opt/anaconda3/envs/textS/lib/python3.8/site-packages/requests/models.py", line 816, in generate
    yield from self.raw.stream(chunk_size, decode_content=True)
  File "/Users/snehalmachan/opt/anaconda3/envs/textS/lib/python3.8/site-packages/urllib3/response.py", line 628, in stream
    data = self.read(amt=amt, decode_content=decode_content)
  File "/Users/snehalmachan/opt/anaconda3/envs/textS/lib/python3.8/site-packages/urllib3/response.py", line 593, in read
    raise IncompleteRead(self._fp_bytes_read, self.length_remaining)
  File "/Users/snehalmachan/opt/anaconda3/envs/textS/lib/python3.8/contextlib.py", line 131, in __exit__
    self.gen.throw(type, value, traceback)
  File "/Users/snehalmachan/opt/anaconda3/envs/textS/lib/python3.8/site-packages/urllib3/response.py", line 449, in _error_catcher
    raise ReadTimeoutError(self._pool, None, "Read timed out.")
urllib3.exceptions.ReadTimeoutError: HTTPSConnectionPool(host='cdn-lfs.huggingface.co', port=443): Read timed out.

During handling of the above exception, another exception occurred:

Traceback (most recent call last):
  File "/Users/snehalmachan/opt/anaconda3/envs/textS/lib/python3.8/site-packages/huggingface_hub/file_download.py", line 541, in http_get
    for chunk in r.iter_content(chunk_size=DOWNLOAD_CHUNK_SIZE):
  File "/Users/snehalmachan/opt/anaconda3/envs/textS/lib/python3.8/site-packages/requests/models.py", line 822, in generate
    raise ConnectionError(e)
requests.exceptions.ConnectionError: HTTPSConnectionPool(host='cdn-lfs.huggingface.co', port=443): Read timed out.

During handling of the above exception, another exception occurred:

Traceback (most recent call last):
  File "/Users/snehalmachan/opt/anaconda3/envs/textS/lib/python3.8/site-packages/urllib3/response.py", line 444, in _error_catcher
    yield
  File "/Users/snehalmachan/opt/anaconda3/envs/textS/lib/python3.8/site-packages/urllib3/response.py", line 567, in read
    data = self._fp_read(amt) if not fp_closed else b""
  File "/Users/snehalmachan/opt/anaconda3/envs/textS/lib/python3.8/site-packages/urllib3/response.py", line 533, in _fp_read
    return self._fp.read(amt) if amt is not None else self._fp.read()
  File "/Users/snehalmachan/opt/anaconda3/envs/textS/lib/python3.8/http/client.py", line 459, in read
    n = self.readinto(b)
  File "/Users/snehalmachan/opt/anaconda3/envs/textS/lib/python3.8/http/client.py", line 503, in readinto
    n = self.fp.readinto(b)
  File "/Users/snehalmachan/opt/anaconda3/envs/textS/lib/python3.8/socket.py", line 669, in readinto
    return self._sock.recv_into(b)
  File "/Users/snehalmachan/opt/anaconda3/envs/textS/lib/python3.8/ssl.py", line 1274, in recv_into
    return self.read(nbytes, buffer)
  File "/Users/snehalmachan/opt/anaconda3/envs/textS/lib/python3.8/ssl.py", line 1132, in read
    return self._sslobj.read(len, buffer)
socket.timeout: The read operation timed out

During handling of the above exception, another exception occurred:

Traceback (most recent call last):
  File "/Users/snehalmachan/opt/anaconda3/envs/textS/lib/python3.8/site-packages/requests/models.py", line 816, in generate
    yield from self.raw.stream(chunk_size, decode_content=True)
  File "/Users/snehalmachan/opt/anaconda3/envs/textS/lib/python3.8/site-packages/urllib3/response.py", line 628, in stream
    data = self.read(amt=amt, decode_content=decode_content)
  File "/Users/snehalmachan/opt/anaconda3/envs/textS/lib/python3.8/site-packages/urllib3/response.py", line 593, in read
    raise IncompleteRead(self._fp_bytes_read, self.length_remaining)
  File "/Users/snehalmachan/opt/anaconda3/envs/textS/lib/python3.8/contextlib.py", line 131, in __exit__
    self.gen.throw(type, value, traceback)
  File "/Users/snehalmachan/opt/anaconda3/envs/textS/lib/python3.8/site-packages/urllib3/response.py", line 449, in _error_catcher
    raise ReadTimeoutError(self._pool, None, "Read timed out.")
urllib3.exceptions.ReadTimeoutError: HTTPSConnectionPool(host='cdn-lfs.huggingface.co', port=443): Read timed out.

During handling of the above exception, another exception occurred:

Traceback (most recent call last):
  File "/Users/snehalmachan/opt/anaconda3/envs/textS/lib/python3.8/site-packages/huggingface_hub/file_download.py", line 541, in http_get
    for chunk in r.iter_content(chunk_size=DOWNLOAD_CHUNK_SIZE):
  File "/Users/snehalmachan/opt/anaconda3/envs/textS/lib/python3.8/site-packages/requests/models.py", line 822, in generate
    raise ConnectionError(e)
requests.exceptions.ConnectionError: HTTPSConnectionPool(host='cdn-lfs.huggingface.co', port=443): Read timed out.

During handling of the above exception, another exception occurred:

Traceback (most recent call last):
  File "/Users/snehalmachan/opt/anaconda3/envs/textS/lib/python3.8/site-packages/urllib3/connection.py", line 174, in _new_conn
    conn = connection.create_connection(
  File "/Users/snehalmachan/opt/anaconda3/envs/textS/lib/python3.8/site-packages/urllib3/util/connection.py", line 72, in create_connection
    for res in socket.getaddrinfo(host, port, family, socket.SOCK_STREAM):
  File "/Users/snehalmachan/opt/anaconda3/envs/textS/lib/python3.8/socket.py", line 918, in getaddrinfo
    for res in _socket.getaddrinfo(host, port, family, type, proto, flags):
socket.gaierror: [Errno 8] nodename nor servname provided, or not known

During handling of the above exception, another exception occurred:

Traceback (most recent call last):
  File "/Users/snehalmachan/opt/anaconda3/envs/textS/lib/python3.8/site-packages/urllib3/connectionpool.py", line 715, in urlopen
    httplib_response = self._make_request(
  File "/Users/snehalmachan/opt/anaconda3/envs/textS/lib/python3.8/site-packages/urllib3/connectionpool.py", line 404, in _make_request
    self._validate_conn(conn)
  File "/Users/snehalmachan/opt/anaconda3/envs/textS/lib/python3.8/site-packages/urllib3/connectionpool.py", line 1058, in _validate_conn
    conn.connect()
  File "/Users/snehalmachan/opt/anaconda3/envs/textS/lib/python3.8/site-packages/urllib3/connection.py", line 363, in connect
    self.sock = conn = self._new_conn()
  File "/Users/snehalmachan/opt/anaconda3/envs/textS/lib/python3.8/site-packages/urllib3/connection.py", line 186, in _new_conn
    raise NewConnectionError(
urllib3.exceptions.NewConnectionError: <urllib3.connection.HTTPSConnection object at 0x7f7b27251820>: Failed to establish a new connection: [Errno 8] nodename nor servname provided, or not known

During handling of the above exception, another exception occurred:

Traceback (most recent call last):
  File "/Users/snehalmachan/opt/anaconda3/envs/textS/lib/python3.8/site-packages/requests/adapters.py", line 486, in send
    resp = conn.urlopen(
  File "/Users/snehalmachan/opt/anaconda3/envs/textS/lib/python3.8/site-packages/urllib3/connectionpool.py", line 799, in urlopen
    retries = retries.increment(
  File "/Users/snehalmachan/opt/anaconda3/envs/textS/lib/python3.8/site-packages/urllib3/util/retry.py", line 592, in increment
    raise MaxRetryError(_pool, url, error or ResponseError(cause))
urllib3.exceptions.MaxRetryError: HTTPSConnectionPool(host='cdn-lfs.huggingface.co', port=443): Max retries exceeded with url: /google/pegasus-cnn_dailymail/cf34e28157605d3ced3bd184820ea2a9d9a30b69f4bb1df4aaa4145d0850290e?response-content-disposition=attachment%3B+filename*%3DUTF-8%27%27pytorch_model.bin%3B+filename%3D%22pytorch_model.bin%22%3B&response-content-type=application%2Foctet-stream&Expires=1701364193&Policy=eyJTdGF0ZW1lbnQiOlt7IkNvbmRpdGlvbiI6eyJEYXRlTGVzc1RoYW4iOnsiQVdTOkVwb2NoVGltZSI6MTcwMTM2NDE5M319LCJSZXNvdXJjZSI6Imh0dHBzOi8vY2RuLWxmcy5odWdnaW5nZmFjZS5jby9nb29nbGUvcGVnYXN1cy1jbm5fZGFpbHltYWlsL2NmMzRlMjgxNTc2MDVkM2NlZDNiZDE4NDgyMGVhMmE5ZDlhMzBiNjlmNGJiMWRmNGFhYTQxNDVkMDg1MDI5MGU~cmVzcG9uc2UtY29udGVudC1kaXNwb3NpdGlvbj0qJnJlc3BvbnNlLWNvbnRlbnQtdHlwZT0qIn1dfQ__&Signature=Zi1gai~jzGappSX6X6~1FsVA47q2sSKkxEp52CYRSecohaAjeVwly2N~m2AcwaCB3XTjxq2JtB~cZuwPSiEkBoBtQIwmwKWuMa5JU-qOGxqbzmPsd-ssWdo3GlpsHx13u8fJCSREZzyXxBLyLEohvswE4f2RDrbJFbfURDPTWq3Aru6EuZZHutFjxDfdzjNgHxi4erjWPMQwhWLnc0hsd-r5cB9kL8OQ87a-pd5BGTcwPrAhXkbKdJcnc758VOkIaQokVowbumL1MvUVwGDlZubVStzjlpmRaLcIZV40PV3Y5O0NbGoTitvhLoDPdRsiC26evbZF6TVUB~nOmqOGKA__&Key-Pair-Id=KVTP0A1DKRTAX (Caused by NewConnectionError('<urllib3.connection.HTTPSConnection object at 0x7f7b27251820>: Failed to establish a new connection: [Errno 8] nodename nor servname provided, or not known'))

During handling of the above exception, another exception occurred:

Traceback (most recent call last):
  File "main.py", line 47, in <module>
    data_transformation.main()
  File "/Users/snehalmachan/Coding/textsummarizer/src/textsummarizer/pipeline/stage_04_model_trainer.py", line 12, in main
    model_trainer_config.train()
  File "/Users/snehalmachan/Coding/textsummarizer/src/textsummarizer/components/model_trainer.py", line 15, in train
    model_pegasus= AutoModelForSeq2SeqLM.from_pretrained(self.config.model_ckpt).to(device)
  File "/Users/snehalmachan/opt/anaconda3/envs/textS/lib/python3.8/site-packages/transformers/models/auto/auto_factory.py", line 566, in from_pretrained
    return model_class.from_pretrained(
  File "/Users/snehalmachan/opt/anaconda3/envs/textS/lib/python3.8/site-packages/transformers/modeling_utils.py", line 3057, in from_pretrained
    resolved_archive_file = cached_file(
  File "/Users/snehalmachan/opt/anaconda3/envs/textS/lib/python3.8/site-packages/transformers/utils/hub.py", line 430, in cached_file
    resolved_file = hf_hub_download(
  File "/Users/snehalmachan/opt/anaconda3/envs/textS/lib/python3.8/site-packages/huggingface_hub/utils/_validators.py", line 118, in _inner_fn
    return fn(*args, **kwargs)
  File "/Users/snehalmachan/opt/anaconda3/envs/textS/lib/python3.8/site-packages/huggingface_hub/file_download.py", line 1461, in hf_hub_download
    http_get(
  File "/Users/snehalmachan/opt/anaconda3/envs/textS/lib/python3.8/site-packages/huggingface_hub/file_download.py", line 558, in http_get
    return http_get(
  File "/Users/snehalmachan/opt/anaconda3/envs/textS/lib/python3.8/site-packages/huggingface_hub/file_download.py", line 558, in http_get
    return http_get(
  File "/Users/snehalmachan/opt/anaconda3/envs/textS/lib/python3.8/site-packages/huggingface_hub/file_download.py", line 558, in http_get
    return http_get(
  [Previous line repeated 1 more time]
  File "/Users/snehalmachan/opt/anaconda3/envs/textS/lib/python3.8/site-packages/huggingface_hub/file_download.py", line 468, in http_get
    r = _request_wrapper(
  File "/Users/snehalmachan/opt/anaconda3/envs/textS/lib/python3.8/site-packages/huggingface_hub/file_download.py", line 425, in _request_wrapper
    response = get_session().request(method=method, url=url, **params)
  File "/Users/snehalmachan/opt/anaconda3/envs/textS/lib/python3.8/site-packages/requests/sessions.py", line 589, in request
    resp = self.send(prep, **send_kwargs)
  File "/Users/snehalmachan/opt/anaconda3/envs/textS/lib/python3.8/site-packages/requests/sessions.py", line 703, in send
    r = adapter.send(request, **kwargs)
  File "/Users/snehalmachan/opt/anaconda3/envs/textS/lib/python3.8/site-packages/huggingface_hub/utils/_http.py", line 63, in send
    return super().send(request, *args, **kwargs)
  File "/Users/snehalmachan/opt/anaconda3/envs/textS/lib/python3.8/site-packages/requests/adapters.py", line 519, in send
    raise ConnectionError(e, request=request)
requests.exceptions.ConnectionError: (MaxRetryError("HTTPSConnectionPool(host='cdn-lfs.huggingface.co', port=443): Max retries exceeded with url: /google/pegasus-cnn_dailymail/cf34e28157605d3ced3bd184820ea2a9d9a30b69f4bb1df4aaa4145d0850290e?response-content-disposition=attachment%3B+filename*%3DUTF-8%27%27pytorch_model.bin%3B+filename%3D%22pytorch_model.bin%22%3B&response-content-type=application%2Foctet-stream&Expires=1701364193&Policy=eyJTdGF0ZW1lbnQiOlt7IkNvbmRpdGlvbiI6eyJEYXRlTGVzc1RoYW4iOnsiQVdTOkVwb2NoVGltZSI6MTcwMTM2NDE5M319LCJSZXNvdXJjZSI6Imh0dHBzOi8vY2RuLWxmcy5odWdnaW5nZmFjZS5jby9nb29nbGUvcGVnYXN1cy1jbm5fZGFpbHltYWlsL2NmMzRlMjgxNTc2MDVkM2NlZDNiZDE4NDgyMGVhMmE5ZDlhMzBiNjlmNGJiMWRmNGFhYTQxNDVkMDg1MDI5MGU~cmVzcG9uc2UtY29udGVudC1kaXNwb3NpdGlvbj0qJnJlc3BvbnNlLWNvbnRlbnQtdHlwZT0qIn1dfQ__&Signature=Zi1gai~jzGappSX6X6~1FsVA47q2sSKkxEp52CYRSecohaAjeVwly2N~m2AcwaCB3XTjxq2JtB~cZuwPSiEkBoBtQIwmwKWuMa5JU-qOGxqbzmPsd-ssWdo3GlpsHx13u8fJCSREZzyXxBLyLEohvswE4f2RDrbJFbfURDPTWq3Aru6EuZZHutFjxDfdzjNgHxi4erjWPMQwhWLnc0hsd-r5cB9kL8OQ87a-pd5BGTcwPrAhXkbKdJcnc758VOkIaQokVowbumL1MvUVwGDlZubVStzjlpmRaLcIZV40PV3Y5O0NbGoTitvhLoDPdRsiC26evbZF6TVUB~nOmqOGKA__&Key-Pair-Id=KVTP0A1DKRTAX (Caused by NewConnectionError('<urllib3.connection.HTTPSConnection object at 0x7f7b27251820>: Failed to establish a new connection: [Errno 8] nodename nor servname provided, or not known'))"), '(Request ID: 92aaa4f5-4af8-4af0-bf96-07e3c9237be7)')
[2023-11-30 12:21:35,412: INFO: main: >>>>>>>>>> stage Model Training stage started <<<<<<<<<<]
[2023-11-30 12:21:35,415: INFO: common: yaml file: config/config.yaml loaded successfully]
[2023-11-30 12:21:35,421: INFO: common: yaml file: params.yaml loaded successfully]
[2023-11-30 12:21:35,422: INFO: common: created directory at :artifacts]
[2023-11-30 12:21:35,422: INFO: common: created directory at :artifacts/model_trainer]
[2023-11-30 12:30:28,305: ERROR: main: 'ModelTrainerConfig' object has no attribute 'per_device_eval_batch_size']
Traceback (most recent call last):
  File "main.py", line 47, in <module>
    data_transformation.main()
  File "/Users/snehalmachan/Coding/textsummarizer/src/textsummarizer/pipeline/stage_04_model_trainer.py", line 12, in main
    model_trainer_config.train()
  File "/Users/snehalmachan/Coding/textsummarizer/src/textsummarizer/components/model_trainer.py", line 26, in train
    per_device_eval_batch_size=self.config.per_device_eval_batch_size,
AttributeError: 'ModelTrainerConfig' object has no attribute 'per_device_eval_batch_size'
[2023-11-30 12:35:26,484: INFO: main: >>>>>>>>>> stage Model Training stage started <<<<<<<<<<]
[2023-11-30 12:35:26,488: INFO: common: yaml file: config/config.yaml loaded successfully]
[2023-11-30 12:35:26,492: INFO: common: yaml file: params.yaml loaded successfully]
[2023-11-30 12:35:26,493: INFO: common: created directory at :artifacts]
[2023-11-30 12:35:26,493: INFO: common: created directory at :artifacts/model_trainer]
[2023-11-30 12:35:26,493: ERROR: main: __init__() got an unexpected keyword argument 'per_device_eval_batch_size']
Traceback (most recent call last):
  File "main.py", line 47, in <module>
    data_transformation.main()
  File "/Users/snehalmachan/Coding/textsummarizer/src/textsummarizer/pipeline/stage_04_model_trainer.py", line 10, in main
    model_trainer_config= config.get_model_trainer_config()
  File "/Users/snehalmachan/Coding/textsummarizer/src/textsummarizer/config/configuration.py", line 62, in get_model_trainer_config
    model_trainer_config= ModelTrainerConfig(
TypeError: __init__() got an unexpected keyword argument 'per_device_eval_batch_size'
[2023-11-30 12:36:53,930: INFO: main: >>>>>>>>>> stage Model Training stage started <<<<<<<<<<]
[2023-11-30 12:36:53,934: INFO: common: yaml file: config/config.yaml loaded successfully]
[2023-11-30 12:36:53,940: INFO: common: yaml file: params.yaml loaded successfully]
[2023-11-30 12:36:53,941: INFO: common: created directory at :artifacts]
[2023-11-30 12:36:53,941: INFO: common: created directory at :artifacts/model_trainer]
[2023-11-30 12:37:39,004: ERROR: main: '>' not supported between instances of 'str' and 'int']
Traceback (most recent call last):
  File "main.py", line 47, in <module>
    data_transformation.main()
  File "/Users/snehalmachan/Coding/textsummarizer/src/textsummarizer/pipeline/stage_04_model_trainer.py", line 12, in main
    model_trainer_config.train()
  File "/Users/snehalmachan/Coding/textsummarizer/src/textsummarizer/components/model_trainer.py", line 21, in train
    trainer_args= TrainingArguments(
  File "<string>", line 117, in __init__
  File "/Users/snehalmachan/opt/anaconda3/envs/textS/lib/python3.8/site-packages/transformers/training_args.py", line 1316, in __post_init__
    if self.evaluation_strategy == IntervalStrategy.STEPS and self.eval_steps > 1:
TypeError: '>' not supported between instances of 'str' and 'int'
[2023-11-30 12:45:13,942: INFO: main: >>>>>>>>>> stage Model Training stage started <<<<<<<<<<]
[2023-11-30 12:45:13,946: INFO: common: yaml file: config/config.yaml loaded successfully]
[2023-11-30 12:45:13,952: INFO: common: yaml file: params.yaml loaded successfully]
[2023-11-30 12:45:13,952: INFO: common: created directory at :artifacts]
[2023-11-30 12:45:13,953: INFO: common: created directory at :artifacts/model_trainer]
[2023-11-30 12:45:50,043: ERROR: main: '>' not supported between instances of 'str' and 'int']
Traceback (most recent call last):
  File "main.py", line 47, in <module>
    data_transformation.main()
  File "/Users/snehalmachan/Coding/textsummarizer/src/textsummarizer/pipeline/stage_04_model_trainer.py", line 12, in main
    model_trainer_config.train()
  File "/Users/snehalmachan/Coding/textsummarizer/src/textsummarizer/components/model_trainer.py", line 21, in train
    trainer_args= TrainingArguments(
  File "<string>", line 117, in __init__
  File "/Users/snehalmachan/opt/anaconda3/envs/textS/lib/python3.8/site-packages/transformers/training_args.py", line 1316, in __post_init__
    if self.evaluation_strategy == IntervalStrategy.STEPS and self.eval_steps > 1:
TypeError: '>' not supported between instances of 'str' and 'int'
[2023-11-30 12:46:05,821: INFO: main: >>>>>>>>>> stage Model Training stage started <<<<<<<<<<]
[2023-11-30 12:46:05,826: INFO: common: yaml file: config/config.yaml loaded successfully]
[2023-11-30 12:46:05,830: INFO: common: yaml file: params.yaml loaded successfully]
[2023-11-30 12:46:05,830: INFO: common: created directory at :artifacts]
[2023-11-30 12:46:05,831: INFO: common: created directory at :artifacts/model_trainer]
[2023-11-30 12:46:48,885: ERROR: main: '>' not supported between instances of 'str' and 'int']
Traceback (most recent call last):
  File "main.py", line 47, in <module>
    data_transformation.main()
  File "/Users/snehalmachan/Coding/textsummarizer/src/textsummarizer/pipeline/stage_04_model_trainer.py", line 12, in main
    model_trainer_config.train()
  File "/Users/snehalmachan/Coding/textsummarizer/src/textsummarizer/components/model_trainer.py", line 21, in train
    trainer_args= TrainingArguments(
  File "<string>", line 117, in __init__
  File "/Users/snehalmachan/opt/anaconda3/envs/textS/lib/python3.8/site-packages/transformers/training_args.py", line 1316, in __post_init__
    if self.evaluation_strategy == IntervalStrategy.STEPS and self.eval_steps > 1:
TypeError: '>' not supported between instances of 'str' and 'int'
[2023-11-30 12:49:37,561: INFO: main: >>>>>>>>>> stage Model Training stage started <<<<<<<<<<]
[2023-11-30 12:49:37,564: INFO: common: yaml file: config/config.yaml loaded successfully]
[2023-11-30 12:49:37,569: INFO: common: yaml file: params.yaml loaded successfully]
[2023-11-30 12:49:37,571: INFO: common: created directory at :artifacts]
[2023-11-30 12:49:37,571: INFO: common: created directory at :artifacts/model_trainer]
[2023-11-30 12:50:20,503: ERROR: main: '>' not supported between instances of 'str' and 'int']
Traceback (most recent call last):
  File "main.py", line 47, in <module>
    data_transformation.main()
  File "/Users/snehalmachan/Coding/textsummarizer/src/textsummarizer/pipeline/stage_04_model_trainer.py", line 12, in main
    model_trainer_config.train()
  File "/Users/snehalmachan/Coding/textsummarizer/src/textsummarizer/components/model_trainer.py", line 21, in train
    trainer_args= TrainingArguments(
  File "<string>", line 117, in __init__
  File "/Users/snehalmachan/opt/anaconda3/envs/textS/lib/python3.8/site-packages/transformers/training_args.py", line 1316, in __post_init__
    if self.evaluation_strategy == IntervalStrategy.STEPS and self.eval_steps > 1:
TypeError: '>' not supported between instances of 'str' and 'int'
[2023-11-30 13:01:47,997: INFO: main: >>>>>>>>>> stage Model Training stage started <<<<<<<<<<]
[2023-11-30 13:01:48,001: INFO: common: yaml file: config/config.yaml loaded successfully]
[2023-11-30 13:01:48,009: INFO: common: yaml file: params.yaml loaded successfully]
[2023-11-30 13:01:48,010: INFO: common: created directory at :artifacts]
[2023-11-30 13:01:48,010: INFO: common: created directory at :artifacts/model_trainer]
[2023-11-30 13:02:25,116: ERROR: main: '>' not supported between instances of 'str' and 'int']
Traceback (most recent call last):
  File "main.py", line 47, in <module>
    data_transformation.main()
  File "/Users/snehalmachan/Coding/textsummarizer/src/textsummarizer/pipeline/stage_04_model_trainer.py", line 12, in main
    model_trainer_config.train()
  File "/Users/snehalmachan/Coding/textsummarizer/src/textsummarizer/components/model_trainer.py", line 21, in train
    trainer_args= TrainingArguments(
  File "<string>", line 117, in __init__
  File "/Users/snehalmachan/opt/anaconda3/envs/textS/lib/python3.8/site-packages/transformers/training_args.py", line 1316, in __post_init__
    if self.evaluation_strategy == IntervalStrategy.STEPS and self.eval_steps > 1:
TypeError: '>' not supported between instances of 'str' and 'int'
[2023-11-30 13:05:35,650: INFO: main: >>>>>>>>>> stage Data Ingestion stage started <<<<<<<<<<]
[2023-11-30 13:05:35,654: INFO: common: yaml file: config/config.yaml loaded successfully]
[2023-11-30 13:05:35,658: INFO: common: yaml file: params.yaml loaded successfully]
[2023-11-30 13:05:35,659: INFO: common: created directory at :artifacts]
[2023-11-30 13:05:35,660: INFO: common: created directory at :artifacts/data_ingestion]
[2023-11-30 13:05:46,415: INFO: data_ingestion: artifacts/data_ingestion/data.zip download! with following info: 
Connection: close
Content-Length: 24441500
Cache-Control: max-age=300
Content-Security-Policy: default-src 'none'; style-src 'unsafe-inline'; sandbox
Content-Type: application/zip
ETag: "165933e50795792296f76b85aaf91d3eb23e87d0eae076c6e4098708d6f973f4"
Strict-Transport-Security: max-age=31536000
X-Content-Type-Options: nosniff
X-Frame-Options: deny
X-XSS-Protection: 1; mode=block
X-GitHub-Request-Id: CEE6:C1464:AF128:124749:65683B48
Accept-Ranges: bytes
Date: Thu, 30 Nov 2023 07:35:39 GMT
Via: 1.1 varnish
X-Served-By: cache-hyd1100022-HYD
X-Cache: MISS
X-Cache-Hits: 0
X-Timer: S1701329737.594590,VS0,VE2508
Vary: Authorization,Accept-Encoding,Origin
Access-Control-Allow-Origin: *
Cross-Origin-Resource-Policy: cross-origin
X-Fastly-Request-ID: 2634e3e7b044ea4f0369ff9aa8a9e27996d35452
Expires: Thu, 30 Nov 2023 07:40:39 GMT
Source-Age: 2

]
[2023-11-30 13:05:47,035: INFO: main: >>>>>>>>>> stage Data Ingestion stage completed started <<<<

x============x<<<<<<]
[2023-11-30 13:05:47,035: INFO: main: >>>>>>>>>> stage Data Validation stage started <<<<<<<<<<]
[2023-11-30 13:05:47,040: INFO: common: yaml file: config/config.yaml loaded successfully]
[2023-11-30 13:05:47,044: INFO: common: yaml file: params.yaml loaded successfully]
[2023-11-30 13:05:47,044: INFO: common: created directory at :artifacts]
[2023-11-30 13:05:47,045: INFO: common: created directory at :artifacts/data_validation]
[2023-11-30 13:05:47,046: INFO: main: >>>>>>>>>> stage Data Validation stage completed started <<<<

x============x<<<<<<]
[2023-11-30 13:05:47,046: INFO: main: >>>>>>>>>> stage Data Transformation stage started <<<<<<<<<<]
[2023-11-30 13:05:47,050: INFO: common: yaml file: config/config.yaml loaded successfully]
[2023-11-30 13:05:47,054: INFO: common: yaml file: params.yaml loaded successfully]
[2023-11-30 13:05:47,054: INFO: common: created directory at :artifacts]
[2023-11-30 13:05:47,054: INFO: common: created directory at :artifacts/data_transformation]
[2023-11-30 13:05:58,233: INFO: main: >>>>>>>>>> stage Data Transformation stage completed started <<<<

x============x<<<<<<]
[2023-11-30 13:05:58,233: INFO: main: >>>>>>>>>> stage Model Training stage started <<<<<<<<<<]
[2023-11-30 13:05:58,236: INFO: common: yaml file: config/config.yaml loaded successfully]
[2023-11-30 13:05:58,238: INFO: common: yaml file: params.yaml loaded successfully]
[2023-11-30 13:05:58,238: INFO: common: created directory at :artifacts]
[2023-11-30 13:05:58,238: INFO: common: created directory at :artifacts/model_trainer]
[2023-11-30 13:06:25,693: ERROR: main: '>' not supported between instances of 'str' and 'int']
Traceback (most recent call last):
  File "main.py", line 47, in <module>
    data_transformation.main()
  File "/Users/snehalmachan/Coding/textsummarizer/src/textsummarizer/pipeline/stage_04_model_trainer.py", line 12, in main
    model_trainer_config.train()
  File "/Users/snehalmachan/Coding/textsummarizer/src/textsummarizer/components/model_trainer.py", line 21, in train
    trainer_args= TrainingArguments(
  File "<string>", line 117, in __init__
  File "/Users/snehalmachan/opt/anaconda3/envs/textS/lib/python3.8/site-packages/transformers/training_args.py", line 1320, in __post_init__
    if self.save_strategy == IntervalStrategy.STEPS and self.save_steps > 1:
TypeError: '>' not supported between instances of 'str' and 'int'
[2023-11-30 13:12:36,332: INFO: main: >>>>>>>>>> stage Data Ingestion stage started <<<<<<<<<<]
[2023-11-30 13:12:36,337: INFO: common: yaml file: config/config.yaml loaded successfully]
[2023-11-30 13:12:36,342: INFO: common: yaml file: params.yaml loaded successfully]
[2023-11-30 13:12:36,343: INFO: common: created directory at :artifacts]
[2023-11-30 13:12:36,343: INFO: common: created directory at :artifacts/data_ingestion]
[2023-11-30 13:12:36,344: INFO: data_ingestion: File already exists of size: ~ 23869 KB]
[2023-11-30 13:12:36,779: INFO: main: >>>>>>>>>> stage Data Ingestion stage completed started <<<<

x============x<<<<<<]
[2023-11-30 13:12:36,779: INFO: main: >>>>>>>>>> stage Data Validation stage started <<<<<<<<<<]
[2023-11-30 13:12:36,782: INFO: common: yaml file: config/config.yaml loaded successfully]
[2023-11-30 13:12:36,784: INFO: common: yaml file: params.yaml loaded successfully]
[2023-11-30 13:12:36,785: INFO: common: created directory at :artifacts]
[2023-11-30 13:12:36,785: INFO: common: created directory at :artifacts/data_validation]
[2023-11-30 13:12:36,787: INFO: main: >>>>>>>>>> stage Data Validation stage completed started <<<<

x============x<<<<<<]
[2023-11-30 13:12:36,787: INFO: main: >>>>>>>>>> stage Data Transformation stage started <<<<<<<<<<]
[2023-11-30 13:12:36,790: INFO: common: yaml file: config/config.yaml loaded successfully]
[2023-11-30 13:12:36,792: INFO: common: yaml file: params.yaml loaded successfully]
[2023-11-30 13:12:36,793: INFO: common: created directory at :artifacts]
[2023-11-30 13:12:36,793: INFO: common: created directory at :artifacts/data_transformation]
[2023-11-30 13:12:39,505: INFO: main: >>>>>>>>>> stage Data Transformation stage completed started <<<<

x============x<<<<<<]
[2023-11-30 13:12:39,505: INFO: main: >>>>>>>>>> stage Model Training stage started <<<<<<<<<<]
[2023-11-30 13:12:39,508: INFO: common: yaml file: config/config.yaml loaded successfully]
[2023-11-30 13:12:39,510: INFO: common: yaml file: params.yaml loaded successfully]
[2023-11-30 13:12:39,510: INFO: common: created directory at :artifacts]
[2023-11-30 13:12:39,510: INFO: common: created directory at :artifacts/model_trainer]
[2023-11-30 13:13:05,761: ERROR: main: '>' not supported between instances of 'str' and 'int']
Traceback (most recent call last):
  File "main.py", line 47, in <module>
    data_transformation.main()
  File "/Users/snehalmachan/Coding/textsummarizer/src/textsummarizer/pipeline/stage_04_model_trainer.py", line 12, in main
    model_trainer_config.train()
  File "/Users/snehalmachan/Coding/textsummarizer/src/textsummarizer/components/model_trainer.py", line 21, in train
    trainer_args= TrainingArguments(
  File "<string>", line 117, in __init__
  File "/Users/snehalmachan/opt/anaconda3/envs/textS/lib/python3.8/site-packages/transformers/training_args.py", line 1320, in __post_init__
    if self.save_strategy == IntervalStrategy.STEPS and self.save_steps > 1:
TypeError: '>' not supported between instances of 'str' and 'int'
[2023-11-30 13:17:25,348: INFO: main: >>>>>>>>>> stage Data Ingestion stage started <<<<<<<<<<]
[2023-11-30 13:17:25,353: INFO: common: yaml file: config/config.yaml loaded successfully]
[2023-11-30 13:17:25,359: INFO: common: yaml file: params.yaml loaded successfully]
[2023-11-30 13:17:25,360: INFO: common: created directory at :artifacts]
[2023-11-30 13:17:25,361: INFO: common: created directory at :artifacts/data_ingestion]
[2023-11-30 13:17:25,361: INFO: data_ingestion: File already exists of size: ~ 23869 KB]
[2023-11-30 13:17:25,870: INFO: main: >>>>>>>>>> stage Data Ingestion stage completed started <<<<

x============x<<<<<<]
[2023-11-30 13:17:25,874: INFO: main: >>>>>>>>>> stage Data Validation stage started <<<<<<<<<<]
[2023-11-30 13:17:25,879: INFO: common: yaml file: config/config.yaml loaded successfully]
[2023-11-30 13:17:25,883: INFO: common: yaml file: params.yaml loaded successfully]
[2023-11-30 13:17:25,883: INFO: common: created directory at :artifacts]
[2023-11-30 13:17:25,883: INFO: common: created directory at :artifacts/data_validation]
[2023-11-30 13:17:25,886: INFO: main: >>>>>>>>>> stage Data Validation stage completed started <<<<

x============x<<<<<<]
[2023-11-30 13:17:25,886: INFO: main: >>>>>>>>>> stage Data Transformation stage started <<<<<<<<<<]
[2023-11-30 13:17:25,890: INFO: common: yaml file: config/config.yaml loaded successfully]
[2023-11-30 13:17:25,892: INFO: common: yaml file: params.yaml loaded successfully]
[2023-11-30 13:17:25,892: INFO: common: created directory at :artifacts]
[2023-11-30 13:17:25,893: INFO: common: created directory at :artifacts/data_transformation]
[2023-11-30 13:17:28,985: INFO: main: >>>>>>>>>> stage Data Transformation stage completed started <<<<

x============x<<<<<<]
[2023-11-30 13:17:28,985: INFO: main: >>>>>>>>>> stage Model Training stage started <<<<<<<<<<]
[2023-11-30 13:17:28,988: INFO: common: yaml file: config/config.yaml loaded successfully]
[2023-11-30 13:17:28,990: INFO: common: yaml file: params.yaml loaded successfully]
[2023-11-30 13:17:28,990: INFO: common: created directory at :artifacts]
[2023-11-30 13:17:28,991: INFO: common: created directory at :artifacts/model_trainer]
[2023-11-30 13:18:01,755: ERROR: main: invalid literal for int() with base 10: '1e6']
Traceback (most recent call last):
  File "main.py", line 47, in <module>
    data_transformation.main()
  File "/Users/snehalmachan/Coding/textsummarizer/src/textsummarizer/pipeline/stage_04_model_trainer.py", line 12, in main
    model_trainer_config.train()
  File "/Users/snehalmachan/Coding/textsummarizer/src/textsummarizer/components/model_trainer.py", line 30, in train
    save_steps= int(self.config.save_steps),
ValueError: invalid literal for int() with base 10: '1e6'
[2023-11-30 13:27:52,193: INFO: main: >>>>>>>>>> stage Data Ingestion stage started <<<<<<<<<<]
[2023-11-30 13:27:52,197: INFO: common: yaml file: config/config.yaml loaded successfully]
[2023-11-30 13:27:52,201: INFO: common: yaml file: params.yaml loaded successfully]
[2023-11-30 13:27:52,201: INFO: common: created directory at :artifacts]
[2023-11-30 13:27:52,201: INFO: common: created directory at :artifacts/data_ingestion]
[2023-11-30 13:27:52,202: INFO: data_ingestion: File already exists of size: ~ 23869 KB]
[2023-11-30 13:27:52,607: INFO: main: >>>>>>>>>> stage Data Ingestion stage completed started <<<<

x============x<<<<<<]
[2023-11-30 13:27:52,607: INFO: main: >>>>>>>>>> stage Data Validation stage started <<<<<<<<<<]
[2023-11-30 13:27:52,610: INFO: common: yaml file: config/config.yaml loaded successfully]
[2023-11-30 13:27:52,612: INFO: common: yaml file: params.yaml loaded successfully]
[2023-11-30 13:27:52,612: INFO: common: created directory at :artifacts]
[2023-11-30 13:27:52,612: INFO: common: created directory at :artifacts/data_validation]
[2023-11-30 13:27:52,615: INFO: main: >>>>>>>>>> stage Data Validation stage completed started <<<<

x============x<<<<<<]
[2023-11-30 13:27:52,615: INFO: main: >>>>>>>>>> stage Data Transformation stage started <<<<<<<<<<]
[2023-11-30 13:27:52,619: INFO: common: yaml file: config/config.yaml loaded successfully]
[2023-11-30 13:27:52,621: INFO: common: yaml file: params.yaml loaded successfully]
[2023-11-30 13:27:52,622: INFO: common: created directory at :artifacts]
[2023-11-30 13:27:52,622: INFO: common: created directory at :artifacts/data_transformation]
[2023-11-30 13:27:54,915: INFO: main: >>>>>>>>>> stage Data Transformation stage completed started <<<<

x============x<<<<<<]
[2023-11-30 13:27:54,915: INFO: main: >>>>>>>>>> stage Model Training stage started <<<<<<<<<<]
[2023-11-30 13:27:54,918: INFO: common: yaml file: config/config.yaml loaded successfully]
[2023-11-30 13:27:54,920: INFO: common: yaml file: params.yaml loaded successfully]
[2023-11-30 13:27:54,921: INFO: common: created directory at :artifacts]
[2023-11-30 13:27:54,921: INFO: common: created directory at :artifacts/model_trainer]
[2023-11-30 13:28:22,815: ERROR: main: '>' not supported between instances of 'str' and 'int']
Traceback (most recent call last):
  File "main.py", line 47, in <module>
    data_transformation.main()
  File "/Users/snehalmachan/Coding/textsummarizer/src/textsummarizer/pipeline/stage_04_model_trainer.py", line 12, in main
    model_trainer_config.train()
  File "/Users/snehalmachan/Coding/textsummarizer/src/textsummarizer/components/model_trainer.py", line 21, in train
    trainer_args= TrainingArguments(
  File "<string>", line 117, in __init__
  File "/Users/snehalmachan/opt/anaconda3/envs/textS/lib/python3.8/site-packages/transformers/training_args.py", line 1320, in __post_init__
    if self.save_strategy == IntervalStrategy.STEPS and self.save_steps > 1:
TypeError: '>' not supported between instances of 'str' and 'int'
[2023-11-30 13:32:30,137: INFO: main: >>>>>>>>>> stage Data Ingestion stage started <<<<<<<<<<]
[2023-11-30 13:32:30,142: INFO: common: yaml file: config/config.yaml loaded successfully]
[2023-11-30 13:32:30,145: INFO: common: yaml file: params.yaml loaded successfully]
[2023-11-30 13:32:30,146: INFO: common: created directory at :artifacts]
[2023-11-30 13:32:30,146: INFO: common: created directory at :artifacts/data_ingestion]
[2023-11-30 13:32:30,146: INFO: data_ingestion: File already exists of size: ~ 23869 KB]
[2023-11-30 13:32:30,578: INFO: main: >>>>>>>>>> stage Data Ingestion stage completed started <<<<

x============x<<<<<<]
[2023-11-30 13:32:30,578: INFO: main: >>>>>>>>>> stage Data Validation stage started <<<<<<<<<<]
[2023-11-30 13:32:30,582: INFO: common: yaml file: config/config.yaml loaded successfully]
[2023-11-30 13:32:30,585: INFO: common: yaml file: params.yaml loaded successfully]
[2023-11-30 13:32:30,585: INFO: common: created directory at :artifacts]
[2023-11-30 13:32:30,586: INFO: common: created directory at :artifacts/data_validation]
[2023-11-30 13:32:30,587: INFO: main: >>>>>>>>>> stage Data Validation stage completed started <<<<

x============x<<<<<<]
[2023-11-30 13:32:30,587: INFO: main: >>>>>>>>>> stage Data Transformation stage started <<<<<<<<<<]
[2023-11-30 13:32:30,592: INFO: common: yaml file: config/config.yaml loaded successfully]
[2023-11-30 13:32:30,594: INFO: common: yaml file: params.yaml loaded successfully]
[2023-11-30 13:32:30,595: INFO: common: created directory at :artifacts]
[2023-11-30 13:32:30,595: INFO: common: created directory at :artifacts/data_transformation]
[2023-11-30 13:32:33,132: INFO: main: >>>>>>>>>> stage Data Transformation stage completed started <<<<

x============x<<<<<<]
[2023-11-30 13:32:33,132: INFO: main: >>>>>>>>>> stage Model Training stage started <<<<<<<<<<]
[2023-11-30 13:32:33,136: INFO: common: yaml file: config/config.yaml loaded successfully]
[2023-11-30 13:32:33,140: INFO: common: yaml file: params.yaml loaded successfully]
[2023-11-30 13:32:33,140: INFO: common: created directory at :artifacts]
[2023-11-30 13:32:33,140: INFO: common: created directory at :artifacts/model_trainer]
[2023-11-30 13:33:00,893: ERROR: main: '>' not supported between instances of 'str' and 'int']
Traceback (most recent call last):
  File "main.py", line 47, in <module>
    data_transformation.main()
  File "/Users/snehalmachan/Coding/textsummarizer/src/textsummarizer/pipeline/stage_04_model_trainer.py", line 12, in main
    model_trainer_config.train()
  File "/Users/snehalmachan/Coding/textsummarizer/src/textsummarizer/components/model_trainer.py", line 21, in train
    trainer_args= TrainingArguments(
  File "<string>", line 117, in __init__
  File "/Users/snehalmachan/opt/anaconda3/envs/textS/lib/python3.8/site-packages/transformers/training_args.py", line 1320, in __post_init__
    if self.save_strategy == IntervalStrategy.STEPS and self.save_steps > 1:
TypeError: '>' not supported between instances of 'str' and 'int'
[2023-11-30 13:53:49,036: INFO: main: >>>>>>>>>> stage Data Ingestion stage started <<<<<<<<<<]
[2023-11-30 13:53:49,039: INFO: common: yaml file: config/config.yaml loaded successfully]
[2023-11-30 13:53:49,041: INFO: common: yaml file: params.yaml loaded successfully]
[2023-11-30 13:53:49,042: INFO: common: created directory at :artifacts]
[2023-11-30 13:53:49,042: INFO: common: created directory at :artifacts/data_ingestion]
[2023-11-30 13:53:49,042: INFO: data_ingestion: File already exists of size: ~ 23869 KB]
[2023-11-30 13:53:49,436: INFO: main: >>>>>>>>>> stage Data Ingestion stage completed started <<<<

x============x<<<<<<]
[2023-11-30 13:53:49,436: INFO: main: >>>>>>>>>> stage Data Validation stage started <<<<<<<<<<]
[2023-11-30 13:53:49,442: INFO: common: yaml file: config/config.yaml loaded successfully]
[2023-11-30 13:53:49,446: INFO: common: yaml file: params.yaml loaded successfully]
[2023-11-30 13:53:49,447: INFO: common: created directory at :artifacts]
[2023-11-30 13:53:49,448: INFO: common: created directory at :artifacts/data_validation]
[2023-11-30 13:53:49,450: INFO: main: >>>>>>>>>> stage Data Validation stage completed started <<<<

x============x<<<<<<]
[2023-11-30 13:53:49,450: INFO: main: >>>>>>>>>> stage Data Transformation stage started <<<<<<<<<<]
[2023-11-30 13:53:49,457: INFO: common: yaml file: config/config.yaml loaded successfully]
[2023-11-30 13:53:49,459: INFO: common: yaml file: params.yaml loaded successfully]
[2023-11-30 13:53:49,460: INFO: common: created directory at :artifacts]
[2023-11-30 13:53:49,460: INFO: common: created directory at :artifacts/data_transformation]
[2023-11-30 13:53:51,783: INFO: main: >>>>>>>>>> stage Data Transformation stage completed started <<<<

x============x<<<<<<]
[2023-11-30 13:53:51,784: INFO: main: >>>>>>>>>> stage Model Training stage started <<<<<<<<<<]
[2023-11-30 13:53:51,788: INFO: common: yaml file: config/config.yaml loaded successfully]
[2023-11-30 13:53:51,790: INFO: common: yaml file: params.yaml loaded successfully]
[2023-11-30 13:53:51,791: INFO: common: created directory at :artifacts]
[2023-11-30 13:53:51,791: INFO: common: created directory at :artifacts/model_trainer]
[2023-11-30 13:53:51,791: ERROR: main: __init__() missing 1 required positional argument: 'save_steps']
Traceback (most recent call last):
  File "main.py", line 47, in <module>
    data_transformation.main()
  File "/Users/snehalmachan/Coding/textsummarizer/src/textsummarizer/pipeline/stage_04_model_trainer.py", line 10, in main
    model_trainer_config= config.get_model_trainer_config()
  File "/Users/snehalmachan/Coding/textsummarizer/src/textsummarizer/config/configuration.py", line 62, in get_model_trainer_config
    model_trainer_config= ModelTrainerConfig(
TypeError: __init__() missing 1 required positional argument: 'save_steps'
[2023-11-30 13:54:17,947: INFO: main: >>>>>>>>>> stage Data Ingestion stage started <<<<<<<<<<]
[2023-11-30 13:54:17,951: INFO: common: yaml file: config/config.yaml loaded successfully]
[2023-11-30 13:54:17,953: INFO: common: yaml file: params.yaml loaded successfully]
[2023-11-30 13:54:17,953: INFO: common: created directory at :artifacts]
[2023-11-30 13:54:17,954: INFO: common: created directory at :artifacts/data_ingestion]
[2023-11-30 13:54:17,955: INFO: data_ingestion: File already exists of size: ~ 23869 KB]
[2023-11-30 13:54:18,336: INFO: main: >>>>>>>>>> stage Data Ingestion stage completed started <<<<

x============x<<<<<<]
[2023-11-30 13:54:18,336: INFO: main: >>>>>>>>>> stage Data Validation stage started <<<<<<<<<<]
[2023-11-30 13:54:18,338: INFO: common: yaml file: config/config.yaml loaded successfully]
[2023-11-30 13:54:18,340: INFO: common: yaml file: params.yaml loaded successfully]
[2023-11-30 13:54:18,340: INFO: common: created directory at :artifacts]
[2023-11-30 13:54:18,341: INFO: common: created directory at :artifacts/data_validation]
[2023-11-30 13:54:18,342: INFO: main: >>>>>>>>>> stage Data Validation stage completed started <<<<

x============x<<<<<<]
[2023-11-30 13:54:18,342: INFO: main: >>>>>>>>>> stage Data Transformation stage started <<<<<<<<<<]
[2023-11-30 13:54:18,345: INFO: common: yaml file: config/config.yaml loaded successfully]
[2023-11-30 13:54:18,347: INFO: common: yaml file: params.yaml loaded successfully]
[2023-11-30 13:54:18,347: INFO: common: created directory at :artifacts]
[2023-11-30 13:54:18,347: INFO: common: created directory at :artifacts/data_transformation]
[2023-11-30 13:54:20,287: INFO: main: >>>>>>>>>> stage Data Transformation stage completed started <<<<

x============x<<<<<<]
[2023-11-30 13:54:20,288: INFO: main: >>>>>>>>>> stage Model Training stage started <<<<<<<<<<]
[2023-11-30 13:54:20,293: INFO: common: yaml file: config/config.yaml loaded successfully]
[2023-11-30 13:54:20,295: INFO: common: yaml file: params.yaml loaded successfully]
[2023-11-30 13:54:20,296: INFO: common: created directory at :artifacts]
[2023-11-30 13:54:20,296: INFO: common: created directory at :artifacts/model_trainer]
[2023-11-30 13:54:51,456: ERROR: main: Using the `Trainer` with `PyTorch` requires `accelerate>=0.20.1`: Please run `pip install transformers[torch]` or `pip install accelerate -U`]
Traceback (most recent call last):
  File "main.py", line 47, in <module>
    data_transformation.main()
  File "/Users/snehalmachan/Coding/textsummarizer/src/textsummarizer/pipeline/stage_04_model_trainer.py", line 12, in main
    model_trainer_config.train()
  File "/Users/snehalmachan/Coding/textsummarizer/src/textsummarizer/components/model_trainer.py", line 21, in train
    trainer_args= TrainingArguments(
  File "<string>", line 117, in __init__
  File "/Users/snehalmachan/opt/anaconda3/envs/textS/lib/python3.8/site-packages/transformers/training_args.py", line 1442, in __post_init__
    and (self.device.type != "cuda")
  File "/Users/snehalmachan/opt/anaconda3/envs/textS/lib/python3.8/site-packages/transformers/training_args.py", line 1887, in device
    return self._setup_devices
  File "/Users/snehalmachan/opt/anaconda3/envs/textS/lib/python3.8/site-packages/transformers/utils/generic.py", line 54, in __get__
    cached = self.fget(obj)
  File "/Users/snehalmachan/opt/anaconda3/envs/textS/lib/python3.8/site-packages/transformers/training_args.py", line 1787, in _setup_devices
    raise ImportError(
ImportError: Using the `Trainer` with `PyTorch` requires `accelerate>=0.20.1`: Please run `pip install transformers[torch]` or `pip install accelerate -U`
[2023-11-30 14:00:18,830: INFO: main: >>>>>>>>>> stage Data Ingestion stage started <<<<<<<<<<]
[2023-11-30 14:00:18,835: INFO: common: yaml file: config/config.yaml loaded successfully]
[2023-11-30 14:00:18,841: INFO: common: yaml file: params.yaml loaded successfully]
[2023-11-30 14:00:18,842: INFO: common: created directory at :artifacts]
[2023-11-30 14:00:18,843: INFO: common: created directory at :artifacts/data_ingestion]
[2023-11-30 14:00:18,843: INFO: data_ingestion: File already exists of size: ~ 23869 KB]
[2023-11-30 14:00:19,244: INFO: main: >>>>>>>>>> stage Data Ingestion stage completed started <<<<

x============x<<<<<<]
[2023-11-30 14:00:19,244: INFO: main: >>>>>>>>>> stage Data Validation stage started <<<<<<<<<<]
[2023-11-30 14:00:19,246: INFO: common: yaml file: config/config.yaml loaded successfully]
[2023-11-30 14:00:19,248: INFO: common: yaml file: params.yaml loaded successfully]
[2023-11-30 14:00:19,248: INFO: common: created directory at :artifacts]
[2023-11-30 14:00:19,248: INFO: common: created directory at :artifacts/data_validation]
[2023-11-30 14:00:19,250: INFO: main: >>>>>>>>>> stage Data Validation stage completed started <<<<

x============x<<<<<<]
[2023-11-30 14:00:19,250: INFO: main: >>>>>>>>>> stage Data Transformation stage started <<<<<<<<<<]
[2023-11-30 14:00:19,254: INFO: common: yaml file: config/config.yaml loaded successfully]
[2023-11-30 14:00:19,256: INFO: common: yaml file: params.yaml loaded successfully]
[2023-11-30 14:00:19,256: INFO: common: created directory at :artifacts]
[2023-11-30 14:00:19,256: INFO: common: created directory at :artifacts/data_transformation]
[2023-11-30 14:00:21,749: INFO: main: >>>>>>>>>> stage Data Transformation stage completed started <<<<

x============x<<<<<<]
[2023-11-30 14:00:21,750: INFO: main: >>>>>>>>>> stage Model Training stage started <<<<<<<<<<]
[2023-11-30 14:00:21,756: INFO: common: yaml file: config/config.yaml loaded successfully]
[2023-11-30 14:00:21,757: INFO: common: yaml file: params.yaml loaded successfully]
[2023-11-30 14:00:21,758: INFO: common: created directory at :artifacts]
[2023-11-30 14:00:21,758: INFO: common: created directory at :artifacts/model_trainer]
[2023-11-30 16:31:24,171: INFO: common: yaml file: config/config.yaml loaded successfully]
[2023-11-30 16:31:24,220: INFO: common: yaml file: params.yaml loaded successfully]
[2023-11-30 16:31:24,233: INFO: common: created directory at :artifacts]
[2023-11-30 16:31:44,252: INFO: common: yaml file: config/config.yaml loaded successfully]
[2023-11-30 16:31:44,271: INFO: common: yaml file: params.yaml loaded successfully]
[2023-11-30 16:31:44,292: INFO: common: created directory at :artifacts]
[2023-11-30 16:32:18,195: INFO: common: yaml file: config/config.yaml loaded successfully]
[2023-11-30 16:32:18,205: INFO: common: yaml file: params.yaml loaded successfully]
[2023-11-30 16:32:18,230: INFO: common: created directory at :artifacts]
[2023-11-30 16:32:18,232: INFO: common: created directory at :artifacts/model_trainer]
[2023-12-01 14:51:55,946: INFO: server: Started server process [47130]]
[2023-12-01 14:51:55,947: INFO: on: Waiting for application startup.]
[2023-12-01 14:51:55,948: INFO: on: Application startup complete.]
[2023-12-01 14:51:55,948: INFO: server: Uvicorn running on http://0.0.0.0:8080 (Press CTRL+C to quit)]
[2023-12-01 14:53:00,239: INFO: server: Started server process [47165]]
[2023-12-01 14:53:00,240: INFO: on: Waiting for application startup.]
[2023-12-01 14:53:00,240: INFO: on: Application startup complete.]
[2023-12-01 14:53:00,241: ERROR: server: [Errno 48] error while attempting to bind on address ('0.0.0.0', 8080): address already in use]
[2023-12-01 14:53:00,241: INFO: on: Waiting for application shutdown.]
[2023-12-01 14:53:00,241: INFO: on: Application shutdown complete.]
[2023-12-01 14:53:09,554: INFO: server: Started server process [47182]]
[2023-12-01 14:53:09,554: INFO: on: Waiting for application startup.]
[2023-12-01 14:53:09,555: INFO: on: Application startup complete.]
[2023-12-01 14:53:09,555: ERROR: server: [Errno 48] error while attempting to bind on address ('0.0.0.0', 8080): address already in use]
[2023-12-01 14:53:09,556: INFO: on: Waiting for application shutdown.]
[2023-12-01 14:53:09,556: INFO: on: Application shutdown complete.]
[2023-12-01 14:57:06,603: INFO: server: Started server process [47243]]
[2023-12-01 14:57:06,603: INFO: on: Waiting for application startup.]
[2023-12-01 14:57:06,604: INFO: on: Application startup complete.]
[2023-12-01 14:57:06,604: ERROR: server: [Errno 48] error while attempting to bind on address ('0.0.0.0', 8080): address already in use]
[2023-12-01 14:57:06,605: INFO: on: Waiting for application shutdown.]
[2023-12-01 14:57:06,605: INFO: on: Application shutdown complete.]
[2023-12-01 14:57:46,346: INFO: server: Started server process [47262]]
[2023-12-01 14:57:46,347: INFO: on: Waiting for application startup.]
[2023-12-01 14:57:46,347: INFO: on: Application startup complete.]
[2023-12-01 14:57:46,348: ERROR: server: [Errno 48] error while attempting to bind on address ('0.0.0.0', 8080): address already in use]
[2023-12-01 14:57:46,348: INFO: on: Waiting for application shutdown.]
[2023-12-01 14:57:46,348: INFO: on: Application shutdown complete.]
[2023-12-01 14:58:02,445: INFO: server: Started server process [47284]]
[2023-12-01 14:58:02,445: INFO: on: Waiting for application startup.]
[2023-12-01 14:58:02,446: INFO: on: Application startup complete.]
[2023-12-01 14:58:02,447: ERROR: server: [Errno 48] error while attempting to bind on address ('0.0.0.0', 8080): address already in use]
[2023-12-01 14:58:02,447: INFO: on: Waiting for application shutdown.]
[2023-12-01 14:58:02,447: INFO: on: Application shutdown complete.]
[2023-12-01 14:59:42,288: INFO: server: Started server process [47377]]
[2023-12-01 14:59:42,289: INFO: on: Waiting for application startup.]
[2023-12-01 14:59:42,289: INFO: on: Application startup complete.]
[2023-12-01 14:59:42,290: INFO: server: Uvicorn running on http://0.0.0.0:8080 (Press CTRL+C to quit)]
[2023-12-01 15:00:12,183: INFO: main: >>>>>>>>>> stage Data Ingestion stage started <<<<<<<<<<]
[2023-12-01 15:00:12,188: INFO: common: yaml file: config/config.yaml loaded successfully]
[2023-12-01 15:00:12,193: INFO: common: yaml file: params.yaml loaded successfully]
[2023-12-01 15:00:12,193: INFO: common: created directory at :artifacts]
[2023-12-01 15:00:12,194: INFO: common: created directory at :artifacts/data_ingestion]
[2023-12-01 15:00:12,194: INFO: data_ingestion: File already exists of size: ~ 23869 KB]
[2023-12-01 15:00:12,693: INFO: main: >>>>>>>>>> stage Data Ingestion stage completed started <<<<

x============x<<<<<<]
[2023-12-01 15:00:12,693: INFO: main: >>>>>>>>>> stage Data Validation stage started <<<<<<<<<<]
[2023-12-01 15:00:12,697: INFO: common: yaml file: config/config.yaml loaded successfully]
[2023-12-01 15:00:12,698: INFO: common: yaml file: params.yaml loaded successfully]
[2023-12-01 15:00:12,699: INFO: common: created directory at :artifacts]
[2023-12-01 15:00:12,699: INFO: common: created directory at :artifacts/data_validation]
[2023-12-01 15:00:12,701: INFO: main: >>>>>>>>>> stage Data Validation stage completed started <<<<

x============x<<<<<<]
[2023-12-01 15:00:12,701: INFO: main: >>>>>>>>>> stage Data Transformation stage started <<<<<<<<<<]
[2023-12-01 15:00:12,708: INFO: common: yaml file: config/config.yaml loaded successfully]
[2023-12-01 15:00:12,709: INFO: common: yaml file: params.yaml loaded successfully]
[2023-12-01 15:00:12,710: INFO: common: created directory at :artifacts]
[2023-12-01 15:00:12,710: INFO: common: created directory at :artifacts/data_transformation]
[2023-12-01 15:00:15,007: INFO: main: >>>>>>>>>> stage Data Transformation stage completed started <<<<

x============x<<<<<<]
[2023-12-01 15:00:15,008: INFO: main: >>>>>>>>>> stage Model Training stage started <<<<<<<<<<]
[2023-12-01 15:00:15,013: INFO: common: yaml file: config/config.yaml loaded successfully]
[2023-12-01 15:00:15,015: INFO: common: yaml file: params.yaml loaded successfully]
[2023-12-01 15:00:15,015: INFO: common: created directory at :artifacts]
[2023-12-01 15:00:15,016: INFO: common: created directory at :artifacts/model_trainer]
